<?xml version="1.0"?>

<robot xmlns:sensor="http://playerstage.sourceforge.net/gazebo/xmlschema/#sensor"
       xmlns:controller="http://playerstage.sourceforge.net/gazebo/xmlschema/#controller"
       xmlns:interface="http://playerstage.sourceforge.net/gazebo/xmlschema/#interface"
       xmlns:xacro="http://ros.org/wiki/xacro">

  <include filename="$(find pr2_description)/urdf/tilting_laser_v0/tilting_laser.gazebo.xacro" />
  <include filename="$(find pr2_description)/urdf/tilting_laser_v0/tilting_laser.transmission.xacro" />
  <include filename="$(find pr2_description)/urdf/sensors/hokuyo_lx30_laser.urdf.xacro" />

  <xacro:macro name="pr2_tilting_laser" params="name parent laser_calib_ref *origin">

    <joint name="${name}_mount_joint" type="revolute">
      <axis xyz="0 1 0" />
      <limit lower="-0.785" upper="1.57" effort="0.5292" velocity="10.0" />
      <safety_controller k_position="100" k_velocity="0.05" soft_lower_limit="${-0.785+0.0}" soft_upper_limit="${1.57-0.0}" />
      <calibration reference_position="${laser_calib_ref}" />
      <dynamics damping="0.008" />
      <insert_block name="origin" />
      <parent link="${parent}"/>
      <child link="${name}_mount_link"/>
    </joint>
    <link name="${name}_mount_link">

      <inertial>
        <mass value="0.05" />
        <origin xyz="-0.03 0 -0.03" rpy="0 0 0" />
        <inertia ixx="0.0001" ixy="0" ixz="0" 
                 iyy="0.00001" iyz="0" 
                 izz="0.0001" />
      </inertial>

      <visual name="${name}_mount_visual">
        <origin xyz="0 0 0" rpy="0 0 0" />
        <geometry name="${name}_mount_visual_geom">
          <mesh filename="package://pr2_defs/meshes/hok_tilt.stl" />
        </geometry>
        
        <material name="Red" />
      </visual>

      <collision name="${name}_mount_collision">
        <origin xyz="0 0 0" rpy="0 0 0" />
        <geometry name="${name}_mount_collision_geom" >
          <box size=".001 .001 .001" />
        </geometry>
      </collision>
    </link>

    <xacro:hokuyo_lx30_laser name="${name}" parent="${name}_mount" ros_topic="tilt_scan">
      <origin xyz="0 0 0.03" rpy="0 0 0" />
    </xacro:hokuyo_lx30_laser>

    <!-- extensions -->
    <xacro:pr2_tilting_laser_gazebo name="${name}"/>
    <xacro:pr2_tilting_laser_transmission name="${name}"/>
  </xacro:macro>

</robot>
