<?xml version="1.0"?>

<!-- XML namespaces -->
<robot xmlns:sensor="http://playerstage.sourceforge.net/gazebo/xmlschema/#sensor"
       xmlns:controller="http://playerstage.sourceforge.net/gazebo/xmlschema/#controller"
       xmlns:interface="http://playerstage.sourceforge.net/gazebo/xmlschema/#interface"
       xmlns:xacro="http://ros.org/wiki/xacro">

  <!-- Things that are needed only for Gazebo (not the physical robot).  These include
       sensor and controller plugin specifications -->
  <include filename="$(find pr2_description)/urdf/upper_arm_v0/upper_arm.gazebo.xacro" />
  <include filename="$(find pr2_description)/urdf/upper_arm_v0/upper_arm.transmission.xacro" />
  <include filename="$(find pr2_description)/urdf/common.xacro" />

  <!-- Inertial properties differ slightly for left vs right arm -->
  <property name="uar_xyz1" value= "0.21398" />
  <property name="uar_xyz2" value="-0.01621" />
  <property name="uar_xyz3" value="-0.00020" />
  <property name="uar_ixx"  value= "0.01537748957" />
  <property name="uar_ixy"  value= "0.00375711247" />
  <property name="uar_ixz"  value="-0.00070852914" />
  <property name="uar_iyy"  value= "0.07473670440" />
  <property name="uar_iyz"  value="-0.00017936450" />
  <property name="uar_izz"  value= "0.07608763307" />

  <property name="ual_xyz1" value= "0.21405" />
  <property name="ual_xyz2" value= "0.01658" />
  <property name="ual_xyz3" value="-0.00057" />
  <property name="ual_ixx"  value= "0.01530603856" />
  <property name="ual_ixy"  value="-0.00339324862" />
  <property name="ual_ixz"  value= "0.00060765455" />
  <property name="ual_iyy"  value= "0.07473694455" />
  <property name="ual_iyz"  value="-0.00019953729" />
  <property name="ual_izz"  value= "0.07601594191" />


  <!-- ============================   Upper Arm   ============================ -->

  <xacro:macro name="pr2_upper_arm" params="side parent reflect">

    <joint name="${side}_upper_arm_joint" type="fixed">
      <origin xyz="0 0 0" rpy="0 0 0" />
      <parent link="${parent}"/>
      <child link="${side}_upper_arm_link"/>
    </joint>
    <link name="${side}_upper_arm_link">

      <inertial>
        <!-- NOTE:reflect==-1 for right side, reflect==1 for the left side -->
        <mass value="6.01769" />
        <origin xyz="${0.5*((reflect+1)*ual_xyz1+(1-reflect)*uar_xyz1)} ${0.5*((reflect+1)*ual_xyz2+(1-reflect)*uar_xyz2)} ${0.5*((reflect+1)*ual_xyz3+(1-reflect)*uar_xyz3)}" />
        <inertia  ixx="${0.5*((reflect+1)*ual_ixx+(1-reflect)*uar_ixx)}"
                  ixy="${0.5*((reflect+1)*ual_ixy+(1-reflect)*uar_ixy)}"
                  ixz="${0.5*((reflect+1)*ual_ixz+(1-reflect)*uar_ixz)}"
                  iyy="${0.5*((reflect+1)*ual_iyy+(1-reflect)*uar_iyy)}"
                  iyz="${0.5*((reflect+1)*ual_iyz+(1-reflect)*uar_iyz)}"
                  izz="${0.5*((reflect+1)*ual_izz+(1-reflect)*uar_izz)}" />
      </inertial>

      <visual name="{side}_upper_arm_visual">
        <origin xyz="0 0 0" rpy="0 0 0" />
        <geometry name="${side}_upper_arm_visual_geom">
          <mesh filename="package://pr2_defs/meshes/upper_arm.stl" />
        </geometry>

        <material name="Green" />
      </visual>

      <collision name="${side}_upper_arm_collision">
        <origin xyz="0 0 0" rpy="0 0 0" />
        <geometry name="${side}_upper_arm_collision_geom">
          <mesh filename="package://pr2_defs/meshes/convex/upper_arm_convex.stlb" />
        </geometry>
      </collision>

    </link>

    <!-- Elbow flex -->

    <joint name="${side}_elbow_flex_joint" type="revolute">
      <axis xyz="0 1 0" />
      <limit lower="-2.3" upper="0.1" effort="30" velocity="${VELOCITY_LIMIT_SCALE*5.5}" />
      <safety_controller k_position="100" k_velocity="3" soft_lower_limit="${-2.3+0.25}" soft_upper_limit="${0.1-0.1}" />
      <calibration reference_position="${-1.1606 + cal_r_elbow_flex_flag}"/>
      <dynamics damping="1.0" />
      <origin xyz="0.4 0 0" rpy="0 0 0" />
      <parent link="${side}_upper_arm_link"/>
      <child link="${side}_elbow_flex_link"/>
    </joint>
    <link name="${side}_elbow_flex_link">


      <inertial>
        <mass value="1.90327" />
        <origin xyz="0.01014 0.00032 -0.01211" />
        <inertia  ixx="0.00346541989" ixy="0.00004066825"  ixz="0.00043171614"
                  iyy="0.00441606455"  iyz="-0.00003968914"
                  izz="0.00359156824" />
      </inertial>

      <visual name="${side}_elbow_flex_visual">
        <origin xyz="0 0 0" rpy="0 0 0" />
        <geometry name="${side}_elbow_flex_visual_geom">
          <mesh filename="package://pr2_defs/meshes/elbow_flex.stl" />
        </geometry>

        <material name="Grey" />
      </visual>

      <collision name="${side}_elbow_flex_collision">
        <origin xyz="0 0 0" rpy="0 0 0" />
        <geometry name="${side}_elbow_flex_collision_geom">
          <mesh filename="package://pr2_defs/meshes/convex/elbow_flex_convex.stlb" />
        </geometry>
      </collision>
    </link>

<!-- forearm roll -->

    <joint name="${side}_forearm_roll_joint" type="continuous">
      <axis xyz="-1 0 0" />

      <limit effort="30" velocity="${VELOCITY_LIMIT_SCALE*6}" />
      <safety_controller k_velocity="1" />
      <calibration reference_position="${cal_r_forearm_roll_flag}" />

      <dynamics damping="0.1" />
      <origin xyz="0 0 0" rpy="0 0 0" />
      <parent link="${side}_elbow_flex_link"/>
      <child link="${side}_forearm_roll_link"/>
    </joint>
    <link name="${side}_forearm_roll_link">

      <inertial>
        <!-- dummy masses, to be removed -->
        <mass value="0.1" />
        <origin xyz="0 0 0" />
        <inertia  ixx="0.01" ixy="0.00"  ixz="0.00"
                  iyy="0.01" iyz="0.00"
                  izz="0.01" />
      </inertial>
      <visual name="${side}_forearm_roll_visual"><!-- TODO: need a mesh for this -->
        <origin xyz="0 0 0" rpy="0 0 0" />
        <geometry name="${side}_forearm_roll_visual_geom">
          <mesh filename="package://pr2_defs/meshes/forearm_roll.stl" />
        </geometry>

        <material name="RollLinks" />
      </visual>
      <collision name="${side}_forearm_roll_collision"> <!-- TODO: collision tag should be optional -->
        <origin xyz="0 0 0" rpy="0 0 0" />
        <geometry name="${side}_forearm_roll_collision_geom">
          <box size="0.1 0.1 0.1" />
        </geometry>
      </collision>
    </link>

    <!-- extensions-->
    <xacro:pr2_upper_arm_gazebo side="${side}" />
    <xacro:pr2_upper_arm_transmission side="${side}" />

  </xacro:macro>
</robot>
