<?xml version="1.0"?>
<robot xmlns:sensor="http://playerstage.sourceforge.net/gazebo/xmlschema/#sensor"
       xmlns:controller="http://playerstage.sourceforge.net/gazebo/xmlschema/#controller"
       xmlns:interface="http://playerstage.sourceforge.net/gazebo/xmlschema/#interface"
       xmlns:xacro="http://ros.org/wiki/xacro">

  <include filename="$(find pr2_description)/urdf/torso_v0/torso.gazebo.xacro" />
  <include filename="$(find pr2_description)/urdf/torso_v0/torso.transmission.xacro" />
  <include filename="$(find pr2_description)/urdf/sensors/microstrain_3dmgx2_imu.urdf.xacro" />

  <xacro:macro name="pr2_torso_v0" params="name parent *origin">
    <joint name="${name}_joint" type="prismatic">
      <axis xyz="0 0 1" />
      <limit lower="0.0" upper="0.31" effort="10000" velocity="0.013"/> <!-- alpha tested velocity and effort limits -->
      <safety_controller  k_velocity="400000" soft_lower_limit="${0.0+0.003}" soft_upper_limit="${0.31-0.005}" k_position="1000" />
      <!-- hold both reference_position and upper/lower for tick-tock, remove reference_positiion after verifying upper/lower works with calibration controllers.  if search velocity in pr2_calibration_controllers.yaml is +, the reference_position is rising, if - then it is falling -->
      <calibration reference_position="0.00536" falling="0.00536" />
      <dynamics damping="5000.0" />
      <insert_block name="origin" />
      <parent link="${parent}"/>
      <child link="${name}_link"/>
    </joint>
    <link name="${name}_link">

      <inertial>
        <mass value="36.248046" />
        <origin xyz="-0.1 0 -0.0885" />
        <inertia ixx="2.771653750257" ixy="0.004284522609" ixz="-0.160418504506"
                 iyy="2.510019507959" iyz="0.029664468704" izz="0.526432355569" />
      </inertial>

      <visual name="${name}_visual">
        <origin xyz="0 0 0" rpy="0 0 0" />
        <geometry name="${name}_visual_geom">
          <mesh filename="package://pr2_description/meshes/torso_v0/torso.stl" />
        </geometry>
        
        <material name="Grey2" />
      </visual>

      <collision name="${name}_collision">
        <origin xyz="0 0 0.16" rpy="0 0 0" />
        <geometry name="${name}_collision_geom">
          <!-- arbitrarily chosen collision box by JH, torso collision is not important for now -->
          <box size="0.30 0.620 0.02" />
        </geometry>
      </collision>
    </link>

    <!-- extensions -->
    <xacro:pr2_torso_gazebo_v0 name="${name}" />
    <xacro:pr2_torso_transmission_v0 name="${name}" />

    <!-- imu -->
    <xacro:microstrain_3dmgx2_imu_v0 name="imu" parent="${name}" ros_topic="imu_data" update_rate="100.0">
        <origin xyz="-0.02977 -0.1497 0.164" rpy="0 0 0" />
    </xacro:microstrain_3dmgx2_imu_v0>

  </xacro:macro>


</robot>
