<?xml version="1.0"?>
<robot xmlns:sensor="http://playerstage.sourceforge.net/gazebo/xmlschema/#sensor"
       xmlns:controller="http://playerstage.sourceforge.net/gazebo/xmlschema/#controller"
       xmlns:interface="http://playerstage.sourceforge.net/gazebo/xmlschema/#interface">

  <include filename="$(find pr2_defs)/defs/arm/arm_gazebo.xacro" />
  <include filename="$(find pr2_defs)/defs/arm/arm_transmission.xacro" />

  <property name="M_PI" value="3.1415926535897931" />
  <property name="VELOCITY_LIMIT_SCALE" value="0.6" />

  <property name="shoulder_lift_length" value="0.10" />
  <property name="shoulder_lift_radius" value="0.12" />

  <!-- for non-symmetric upper arm -->
  <property name="uar_xyz1" value= "0.21398" />
  <property name="uar_xyz2" value="-0.01621" />
  <property name="uar_xyz3" value="-0.00020" />
  <property name="uar_ixx"  value= "0.01537748957" />
  <property name="uar_ixy"  value= "0.00375711247" />
  <property name="uar_ixz"  value="-0.00070852914" />
  <property name="uar_iyy"  value= "0.07473670440" />
  <property name="uar_iyz"  value="-0.00017936450" />
  <property name="uar_izz"  value= "0.07608763307" />

  <property name="ual_xyz1" value= "0.21405" />
  <property name="ual_xyz2" value= "0.01658" />
  <property name="ual_xyz3" value="-0.00057" />
  <property name="ual_ixx"  value= "0.01530603856" />
  <property name="ual_ixy"  value="-0.00339324862" />
  <property name="ual_ixz"  value= "0.00060765455" />
  <property name="ual_iyy"  value= "0.07473694455" />
  <property name="ual_iyz"  value="-0.00019953729" />
  <property name="ual_izz"  value= "0.07601594191" />

  <macro name="pr2_shoulder" params="side parent reflect *origin">

    <!-- Shoulder pan -->
    <joint name="${side}_shoulder_pan_joint" type="revolute">
      <axis xyz="0 0 1" />
      <insert_block name="origin" /> <!-- transform from parent link to this joint frame -->
      <parent link="${parent}"/>
      <child link="${side}_shoulder_pan_link"/>
      <limit lower="${reflect*M_PI/4-1.5}"  upper="${reflect*M_PI/4+1.5}"
             effort="30" velocity="${VELOCITY_LIMIT_SCALE*3.48}" />

      <dynamics damping="10.0" />

      <safety_controller k_position="100" k_velocity="10"
                         soft_lower_limit="${reflect*M_PI/4-1.5+0.15}"
                         soft_upper_limit="${reflect*M_PI/4+1.5-0.15}" />

      <!-- joint angle when the rising or the falling flag is activated on PR2 -->
      <calibration  reference_position="${(reflect*M_PI/4)*cal_r_shoulder_pan_gearing+cal_r_shoulder_pan_flag}" />

    </joint>
    <link name="${side}_shoulder_pan_link">


      <inertial>
        <mass value="25.799322" />
        <origin xyz="-0.001201 0.024513 -0.098231" rpy="0 0 0"/>
        <inertia ixx="0.866179142480"  ixy="-0.06086507933"  ixz="-0.12118061183"
                 iyy="0.87421714893"  iyz="-0.05886609911"
                 izz="0.27353821674" />
      </inertial>

      <visual name="${side}_shoulder_pan_visual">
        <origin xyz="0 0 0" rpy="0 0 0" />
        <geometry name="${side}_shoulder_pan_visual_geom">
          <mesh filename="package://pr2_defs/meshes/shoulder_yaw.stl" />
        </geometry>
        <material name="Blue" />
      </visual>

      <collision name="${side}_shoulder_pan_collision">
        <origin xyz="0.0 0 0.0" rpy="0 0 0" />
        <geometry name="${side}_shoulder_pan_collision_geom">
          <mesh filename="package://pr2_defs/meshes/convex/shoulder_yaw_convex.stlb" />
        </geometry>
      </collision>
    </link>

    <!-- Shoulder lift -->
    <joint name="${side}_shoulder_lift_joint" type="revolute">
      <axis xyz="0 1 0"/>

      <!-- Limits updated from Function's CAD values as of 2009_02_24 (link_data.xls) -->
      <limit lower="-0.5236" upper="1.3963"
             effort="30" velocity="${VELOCITY_LIMIT_SCALE*3.47}" />
             
      <safety_controller k_position="100" k_velocity="10"
                         soft_lower_limit="${-0.5236+0.17}" soft_upper_limit="${1.3963-0.05}" />
      <calibration reference_position="${cal_r_shoulder_lift_flag}" />
      <dynamics damping="10.0" />
      <origin xyz="0.1 0 0" rpy="0 0 0" />
      <parent link="${side}_shoulder_pan_link"/>
      <child link="${side}_shoulder_lift_link"/>
    </joint>
    <link name="${side}_shoulder_lift_link">

      <inertial>
        <mass value="2.74988" />
        <origin xyz="0.02195 -0.02664 -0.03127" rpy="0 0 0"/>
        <inertia ixx="0.02105584615" ixy="0.00496704022"  ixz="-0.00194808955"
                 iyy="0.02127223737" iyz="0.00110425490"
                 izz="0.01975753814" />
      </inertial>

      <visual name="${side}_shoulder_lift_visual">
        <origin xyz="0 0 0" rpy="0 0 0" />
        <geometry name="${side}_shoulder_lift_visual_geom">
          <mesh filename="package://pr2_defs/meshes/shoulder_lift.stl" />
        </geometry>
        <material name="Grey" />
      </visual>

      <collision name="${side}_shoulder_lift_collision">
        <origin xyz="0 0 0" rpy="0 0 0" />
        <geometry name="${side}_shoulder_lift_collision_geom">
          <mesh filename="package://pr2_defs/meshes/convex/shoulder_lift_convex.stlb" />
        </geometry>
      </collision>
    </link>

    <!-- Upperarm roll: internal fixed attchment point for upper arm -->

    <joint name="${side}_upper_arm_roll_joint" type="revolute">
      <axis xyz="1 0 0" />
      <origin xyz="0 0 0" rpy="0 0 0" />
      <parent link="${side}_shoulder_lift_link" />
      <child link="${side}_upper_arm_roll_link"/>
      <limit lower="${reflect*1.55-2.35}" upper="${reflect*1.55+2.35}" effort="30" velocity="${VELOCITY_LIMIT_SCALE*5.45}" />
      <safety_controller k_position="100" k_velocity="2" soft_lower_limit="${reflect*1.55-2.35+0.15}" soft_upper_limit="${reflect*1.55+2.35-0.15}" />
      <calibration reference_position="${(reflect*M_PI/2)*cal_r_upper_arm_roll_gearing + cal_r_upper_arm_roll_flag}" />
      <dynamics damping="0.1" />
    </joint>
    <link name="${side}_upper_arm_roll_link">


      <inertial>
        <!-- dummy mass, to be removed -->
        <mass value="0.1" />
        <origin xyz="0.0 0 0" rpy="0 0 0" />
        <inertia  ixx="0.01" ixy="0.00"  ixz="0.00"
                  iyy="0.01" iyz="0.00"
                  izz="0.01" />
      </inertial>
      <visual name="${side}_upper_arm_roll_visual">
        <!-- TODO: This component doesn't actually have a mesh -->
        <origin xyz="0 0 0" rpy="0 0 0" />
        <geometry name="${side}_upper_arm_roll_visual_geom">
          <mesh filename="package://pr2_defs/meshes/upper_arm_roll.stl" />
        </geometry>
        
        <material name="RollLinks" />
      </visual>
      <collision name="${side}_upper_arm_roll_collision">
        <!-- TODO: collision tag should be optional -->
        <origin xyz="0.0 0 0" rpy="0 0 0" />
        <geometry name="${side}_upper_arm_roll_collision_geom">
          <box size="0.1 0.1 0.1" />
        </geometry>
      </collision>
    </link>

  </macro>



  <!-- ============================   Upper Arm   ============================ -->


  <macro name="pr2_upper_arm" params="side parent reflect">

    <joint name="${side}_upper_arm_joint" type="fixed">
      <origin xyz="0 0 0" rpy="0 0 0" />
      <parent link="${parent}"/>
      <child link="${side}_upper_arm_link"/>
    </joint>
    <link name="${side}_upper_arm_link">

      <inertial>
        <!-- NOTE:reflect==-1 for right side, reflect==1 for the left side -->
        <mass value="6.01769" />
        <origin xyz="${0.5*((reflect+1)*ual_xyz1+(1-reflect)*uar_xyz1)} ${0.5*((reflect+1)*ual_xyz2+(1-reflect)*uar_xyz2)} ${0.5*((reflect+1)*ual_xyz3+(1-reflect)*uar_xyz3)}" />
        <inertia  ixx="${0.5*((reflect+1)*ual_ixx+(1-reflect)*uar_ixx)}"
                  ixy="${0.5*((reflect+1)*ual_ixy+(1-reflect)*uar_ixy)}"
                  ixz="${0.5*((reflect+1)*ual_ixz+(1-reflect)*uar_ixz)}"
                  iyy="${0.5*((reflect+1)*ual_iyy+(1-reflect)*uar_iyy)}"
                  iyz="${0.5*((reflect+1)*ual_iyz+(1-reflect)*uar_iyz)}"
                  izz="${0.5*((reflect+1)*ual_izz+(1-reflect)*uar_izz)}" />
      </inertial>

      <visual name="{side}_upper_arm_visual">
        <origin xyz="0 0 0" rpy="0 0 0" />
        <geometry name="${side}_upper_arm_visual_geom">
          <mesh filename="package://pr2_defs/meshes/upper_arm.stl" />
        </geometry>
        
        <material name="Green" />
      </visual>

      <collision name="${side}_upper_arm_collision">
        <origin xyz="0 0 0" rpy="0 0 0" />
        <geometry name="${side}_upper_arm_collision_geom">
          <mesh filename="package://pr2_defs/meshes/convex/upper_arm_convex.stlb" />
        </geometry>
      </collision>

    </link>

    <!-- Elbow flex -->

    <joint name="${side}_elbow_flex_joint" type="revolute">
      <axis xyz="0 1 0" />
      <limit lower="-2.3" upper="0.1" effort="30" velocity="${VELOCITY_LIMIT_SCALE*5.5}" />
      <safety_controller k_position="100" k_velocity="3" soft_lower_limit="${-2.3+0.25}" soft_upper_limit="${0.1-0.1}" />
      <calibration reference_position="${-1.1606 + cal_r_elbow_flex_flag}"/>
      <dynamics damping="1.0" />
      <origin xyz="0.4 0 0" rpy="0 0 0" />
      <parent link="${side}_upper_arm_link"/>
      <child link="${side}_elbow_flex_link"/>
    </joint>
    <link name="${side}_elbow_flex_link">


      <inertial>
        <mass value="1.90327" />
        <origin xyz="0.01014 0.00032 -0.01211" />
        <inertia  ixx="0.00346541989" ixy="0.00004066825"  ixz="0.00043171614"
                  iyy="0.00441606455"  iyz="-0.00003968914"
                  izz="0.00359156824" />
      </inertial>

      <visual name="${side}_elbow_flex_visual">
        <origin xyz="0 0 0" rpy="0 0 0" />
        <geometry name="${side}_elbow_flex_visual_geom">
          <mesh filename="package://pr2_defs/meshes/elbow_flex.stl" />
        </geometry>
        
        <material name="Grey" />
      </visual>

      <collision name="${side}_elbow_flex_collision">
        <origin xyz="0 0 0" rpy="0 0 0" />
        <geometry name="${side}_elbow_flex_collision_geom">
          <mesh filename="package://pr2_defs/meshes/convex/elbow_flex_convex.stlb" />
        </geometry>
      </collision>
    </link>

    <!-- Forearm roll -->

    <joint name="${side}_forearm_roll_joint" type="continuous">
      <axis xyz="-1 0 0" />

      <limit effort="30" velocity="${VELOCITY_LIMIT_SCALE*6}" />
      <safety_controller k_velocity="1" />
      <calibration reference_position="${cal_r_forearm_roll_flag}" />

      <dynamics damping="0.1" />
      <origin xyz="0 0 0" rpy="0 0 0" />
      <parent link="${side}_elbow_flex_link"/>
      <child link="${side}_forearm_roll_link"/>
    </joint>
    <link name="${side}_forearm_roll_link">

      <inertial>
        <!-- dummy masses, to be removed -->
        <mass value="0.1" />
        <origin xyz="0 0 0" />
        <inertia  ixx="0.01" ixy="0.00"  ixz="0.00"
                  iyy="0.01" iyz="0.00"
                  izz="0.01" />
      </inertial>
      <visual name="${side}_forearm_roll_visual"><!-- TODO: need a mesh for this -->
        <origin xyz="0 0 0" rpy="0 0 0" />
        <geometry name="${side}_forearm_roll_visual_geom">
          <mesh filename="package://pr2_defs/meshes/forearm_roll.stl" />
        </geometry>
        
        <material name="RollLinks" />
      </visual>
      <collision name="${side}_forearm_roll_collision"> <!-- TODO: collision tag should be optional -->
        <origin xyz="0 0 0" rpy="0 0 0" />
        <geometry name="${side}_forearm_roll_collision_geom">
          <box size="0.1 0.1 0.1" />
        </geometry>
      </collision>
    </link>

  </macro>


  <!-- ============================   Forearm   ============================ -->

  <macro name="pr2_forearm" params="side parent reflect">

    <joint name="${side}_forearm_joint" type="fixed">
      <origin xyz="0 0 0" rpy="0 0 0" />
      <parent link="${parent}"/>
      <child link="${side}_forearm_link"/>
    </joint>
    <link name="${side}_forearm_link">

      <inertial>
        <mass value="2.57968" />
        <origin xyz="0.18791 -0.00017 -0.00912" />
        <inertia ixx="0.00364857222" ixy="0.00005215877" ixz="0.00071534842"
                 iyy="0.01507736897" iyz="-0.00001310770"
                 izz="0.01659310749" />
      </inertial>

      <visual name="${side}_forearm_visual">
        <origin xyz="0 0 0" rpy="0 0 0" />
        <geometry name="${side}_forearm_visual_geom">
          <mesh filename="package://pr2_defs/meshes/forearm.stl" />
        </geometry>
        
        <material name="Blue" />
      </visual>

      <collision name="${side}_forearm_collision">
        <origin xyz="0 0 0" rpy="0 0 0" />
        <geometry name="${side}_forearm_collision_geom">
          <mesh filename="package://pr2_defs/meshes/convex/forearm_convex.stlb" />
        </geometry>
      </collision>
    </link>

    <!-- Wrist flex -->

    <joint name="${side}_wrist_flex_joint" type="revolute">
      <axis xyz="0 -1 0" />
      <limit lower="-0.1" upper="2.2" effort="200" velocity="${VELOCITY_LIMIT_SCALE*5.13}" />
      <safety_controller k_position="20" k_velocity="4" soft_lower_limit="${-0.1+0.2}" soft_upper_limit="${2.2-0.2}" />
      <dynamics damping="0.1" />
      <calibration reference_position="${0.4363+cal_r_wrist_flex_flag}" />
      <origin xyz="0.32025 0 0" rpy="0 0 0" />
      <parent link="${side}_forearm_link"/>
      <child link="${side}_wrist_flex_link"/>
    </joint>
    <link name="${side}_wrist_flex_link">

      <inertial>
        <mass value="0.61402" />
        <origin xyz="-0.00157 0.0 -0.00075" />
        <inertia ixx="0.00065165722" ixy="0.00000028864" ixz="0.00000303477"
                 iyy="0.00019824443" iyz="-0.00000022645"
                 izz="0.00064450498" />
      </inertial>

      <visual name="${side}_wrist_flex_visual">
        <origin xyz="0 0 0" rpy="0 0 0" />
        <geometry name="${side}_wrist_flex_visual_geom">
          <mesh filename="package://pr2_defs/meshes/wrist_flex.stl" />
        </geometry>
        
        <material name="Grey" />
      </visual>

      <collision name="${side}_wrist_flex_collision">
        <origin xyz="0 0 0" rpy="0 0 0" />
        <geometry name="${side}_wrist_flex_collision_geom">
          <mesh filename="package://pr2_defs/meshes/convex/wrist_flex_convex.stlb" />
        </geometry>
      </collision>
    </link>

    <!-- Wrist roll -->
    <joint name="${side}_wrist_roll_joint" type="continuous">
      <axis xyz="1 0 0" />
      <limit effort="10" velocity="${VELOCITY_LIMIT_SCALE*6}" />
      <safety_controller k_velocity="2" />
      <dynamics damping="0.1" />
      <calibration reference_position="${1.27+cal_r_wrist_roll_flag}" values="1.5 -1" />
      <origin xyz="0 0 0" rpy="0 0 0" />
      <parent link="${side}_wrist_flex_link"/>
      <child link="${side}_wrist_roll_link"/>
    </joint>
    <link name="${side}_wrist_roll_link">
      <inertial>
        <!-- dummy masses, to be removed.  wrist roll masses are on "gripper_palm" -->
        <mass value="0.1" />
        <origin xyz="0 0 0" />
        <inertia ixx="0.01" ixy="0" ixz="0"
                 iyy="0.01" iyz="0"
                 izz="0.01" />
      </inertial>
      <visual name="${side}_wrist_roll_visual">
        <origin xyz="0 0 0" rpy="0 0 0" />
        <geometry name="${side}_wrist_roll_visual_geom">
          <mesh filename="package://pr2_defs/meshes/wrist_roll.stl" />
        </geometry>
        
        <material name="RollLinks" />
      </visual>
      <collision name="${side}_wrist_roll_collision">
        <origin xyz="0.0 0 0" rpy="0 0 0" />
        <geometry name="${side}_wrist_roll_collision_geom">
          <box size="0.01 0.01 0.01" />
        </geometry>
        <verbose value="Yes" />
      </collision>
    </link>

  </macro>



  <macro name="pr2_arm" params="side parent reflect *origin">
    <pr2_shoulder side="${side}" reflect="${reflect}" parent="${parent}">
      <insert_block name="origin" />
    </pr2_shoulder>
    <pr2_upper_arm side="${side}" reflect="${reflect}" parent="${side}_upper_arm_roll_link" />
    <pr2_forearm side="${side}" reflect="${reflect}" parent="${side}_forearm_roll_link" />

    <!-- gazebo -->
    <pr2_shoulder_gazebo side="${side}" />
    <pr2_upper_arm_gazebo side="${side}" />
    <pr2_forearm_gazebo side="${side}" />

    <!-- transmission -->
    <pr2_shoulder_transmission side="${side}" />
    <pr2_upper_arm_transmission side="${side}" />
    <pr2_forearm_transmission side="${side}" />
  </macro>


</robot>
